Workbook

Sheet Test Cases
A1: Facebook | QA Test Case Suite | Functional · Regression · Usability | Tester: Md Sayem Mottakee | Email: sayemmottakee2000@gmail.com
A2: TC ID | B2: Test Case Name | C2: Description | D2: Module | E2: Priority | F2: Severity | G2: Preconditions | H2: Step # | I2: Test Steps | J2: Test Data | K2: Expected Result | L2: Actual Result | M2: Status | N2: Test Type | O2: Environment | P2: Build/Version | Q2: Executed By | R2: Exec. Date | S2: Jira Defect ID | T2: Comments
A3: TC_001 | B3: Register with valid email | C3: New user creates account using valid email, name, DOB, and password. | D3: Registration | E3: High | F3: Critical | G3: Browser open; email not previously registered; internet connected. | H3: 1 | I3: Go to facebook.com → Click 'Create new account' → Fill all fields with valid data → Click 'Sign Up' | J3: Name: Md Sayem Mottakee | Email: sayemmottakee2000@gmail.com | DOB: 01/Jan/1995 | Pass: Test@1234! | K3: Account created; confirmation email sent; user lands on confirm email screen. | M3: Pass | N3: Functional | O3: Chrome 124 | P3: v.2026.04 | Q3: Md Sayem Mottakee | R3: 2026-04-01
A4: TC_002 | B4: Register with already-used email | C4: System rejects registration if the email is already linked to an existing account. | D4: Registration | E4: High | F4: Major | G4: Existing account linked to test email. | H4: 1 | I4: Go to Sign Up → Enter already-registered email → Fill remaining fields → Click Sign Up | J4: Email: sayemmottakee2000@gmail.com (already registered) | K4: Error: 'It looks like you already have an account' displayed. Registration blocked. | M4: Pass | N4: Functional | O4: Chrome 124 | P4: v.2026.04 | Q4: Md Sayem Mottakee | R4: 2026-04-01
A5: TC_003 | B5: Register with invalid email format | C5: System validates email format and prevents submission with malformed email. | D5: Registration | E5: Medium | F5: Major | G5: None. | H5: 1 | I5: Go to Sign Up → Enter invalid email → Fill other fields → Click Sign Up | J5: Email: notanemail@@bad | Pass: Test@1234! | K5: Inline validation error on email field. Form does not submit. | M5: Pass | N5: Functional | O5: Firefox 125 | P5: v.2026.04 | Q5: Md Sayem Mottakee | R5: 2026-04-01
A6: TC_004 | B6: Register with weak password | C6: System enforces password strength and rejects weak passwords. | D6: Registration | E6: High | F6: Major | G6: None. | H6: 1 | I6: Go to Sign Up → Fill valid name/email/DOB → Enter weak password → Click Sign Up | J6: Password: 123456 | K6: Error: 'Choose a more secure password' shown. Account not created. | M6: Pass | N6: Functional | O6: Chrome 124 | P6: v.2026.04 | Q6: Md Sayem Mottakee | R6: 2026-04-02
A7: TC_005 | B7: Register with underage DOB | C7: System blocks registration for users under 13 per policy. | D7: Registration | E7: High | F7: Critical | G7: None. | H7: 1 | I7: Go to Sign Up → Enter DOB yielding age < 13 → Complete other fields → Click Sign Up | J7: DOB: 01/Jan/2015 (age 11) | K7: Error displayed; account creation blocked with age policy message. | M7: Pass | N7: Functional | O7: Chrome 124 | P7: v.2026.04 | Q7: Md Sayem Mottakee | R7: 2026-04-02
A8: TC_006 | B8: Login with valid credentials | C8: Registered user logs in successfully and is directed to News Feed. | D8: Login | E8: High | F8: Critical | G8: Valid registered account exists. | H8: 1 | I8: Go to facebook.com → Enter valid email and password → Click 'Log In' | J8: Email: sayemmottakee2000@gmail.com | Pass: Test@1234! | K8: User lands on News Feed. Name displayed in top nav. | M8: Pass | N8: Smoke | O8: Chrome 124 | P8: v.2026.04 | Q8: Md Sayem Mottakee | R8: 2026-04-01
A9: TC_007 | B9: Login with wrong password | C9: System shows error and does not grant access with incorrect password. | D9: Login | E9: High | F9: Critical | G9: Valid account exists. | H9: 1 | I9: Go to facebook.com → Enter valid email → Enter wrong password → Click Log In | J9: Email: sayemmottakee2000@gmail.com | Pass: WrongPass99 | K9: Error: 'The password you've entered is incorrect.' Login denied. | M9: Pass | N9: Functional | O9: Chrome 124 | P9: v.2026.04 | Q9: Md Sayem Mottakee | R9: 2026-04-01
A10: TC_008 | B10: Login with unregistered email | C10: System shows appropriate error for unknown email. | D10: Login | E10: Medium | F10: Major | G10: None. | H10: 1 | I10: Go to facebook.com → Enter unregistered email → Any password → Click Log In | J10: Email: nobody@fake.net | Pass: Test@1234! | K10: Error: 'The email address you entered isn't connected to an account.' | M10: Pass | N10: Functional | O10: Firefox 125 | P10: v.2026.04 | Q10: Md Sayem Mottakee | R10: 2026-04-01
A11: TC_009 | B11: Account lockout after repeated failed logins | C11: Account temporarily locked after 5 consecutive wrong password attempts. | D11: Login | E11: High | F11: Critical | G11: Valid account exists. | H11: 1 | I11: Attempt login with wrong password 5 times consecutively | J11: Email: sayemmottakee2000@gmail.com | Wrong password repeated 5x | K11: Lockout message displayed. CAPTCHA or cooldown enforced. | M11: Fail | N11: Security | O11: Chrome 124 | P11: v.2026.04 | Q11: Md Sayem Mottakee | R11: 2026-04-02 | S11: FB-2201 | T11: Lockout triggers after 8 attempts, not 5 as per spec
A12: TC_010 | B12: Forgot password — reset via email | C12: User can successfully reset password using the Forgot Password flow. | D12: Login | E12: High | F12: Critical | G12: Account exists; email inbox accessible. | H12: 1 | I12: Click 'Forgotten password?' → Enter email → Click Search → Click 'Send code' → Open email → Enter code → Set new password | J12: Email: sayemmottakee2000@gmail.com | New pass: NewPass@5678! | K12: Password reset. User can log in with new password immediately. | M12: Pass | N12: Regression | O12: Chrome 124 | P12: v.2026.04 | Q12: Md Sayem Mottakee | R12: 2026-04-02
A13: TC_011 | B13: Remember me / stay logged in | C13: Selecting 'Remember me' persists login session across browser restarts. | D13: Login | E13: Medium | F13: Minor | G13: User is on login page. | H13: 1 | I13: Enter valid credentials → Check 'Stay logged in' → Log in → Close browser → Reopen → Navigate to facebook.com | J13: Same browser session, no incognito | K13: User remains logged in; News Feed loads without prompting for credentials. | M13: Pass | N13: Regression | O13: Chrome 124 | P13: v.2026.04 | Q13: Md Sayem Mottakee | R13: 2026-04-02
A14: TC_012 | B14: Login via Facebook mobile app (Android) | C14: User logs in on Android app and News Feed loads correctly. | D14: Login | E14: High | F14: Critical | G14: Facebook app installed on Android 14; account exists. | H14: 1 | I14: Open Facebook app → Enter valid email and password → Tap Log In | J14: Email: sayemmottakee2000@gmail.com | Pass: Test@1234! | K14: App loads News Feed. Stories, posts, and nav bar visible. | M14: Pass | N14: Smoke | O14: Android 14 | P14: v.2026.04 | Q14: Md Sayem Mottakee | R14: 2026-04-02
A15: TC_013 | B15: News Feed loads posts | C15: After login, News Feed displays recent posts from friends and followed pages. | D15: News Feed | E15: High | F15: Critical | G15: User logged in; has friends with recent posts. | H15: 1 | I15: Log in → Observe News Feed on home screen | J15: Account with 50+ friends | K15: News Feed shows posts in order. Text, images, videos load. | M15: Pass | N15: Smoke | O15: Chrome 124 | P15: v.2026.04 | Q15: Md Sayem Mottakee | R15: 2026-04-03
A16: TC_014 | B16: Infinite scroll loads more posts | C16: Scrolling to bottom of News Feed loads additional posts automatically. | D16: News Feed | E16: High | F16: Major | G16: User logged in; News Feed has content. | H16: 1 | I16: Log in → Scroll to bottom of News Feed → Observe if more posts load | J16: N/A | K16: New batch of posts loads seamlessly. Spinner appears briefly during fetch. | M16: Pass | N16: Functional | O16: Chrome 124 | P16: v.2026.04 | Q16: Md Sayem Mottakee | R16: 2026-04-03
A17: TC_015 | B17: Like a post | C17: User can like a post and like count increments immediately. | D17: News Feed | E17: High | F17: Major | G17: User logged in; post visible in feed. | H17: 1 | I17: Find any post in feed → Click the 👍 Like button | J17: N/A | K17: Like button turns blue. Like count increments by 1. Persists on refresh. | M17: Pass | N17: Functional | O17: Chrome 124 | P17: v.2026.04 | Q17: Md Sayem Mottakee | R17: 2026-04-03
A18: TC_016 | B18: React to a post with emoji reaction | C18: User can select an emoji reaction beyond basic Like. | D18: News Feed | E18: Medium | F18: Minor | G18: User logged in; post visible in feed. | H18: 1 | I18: Hover over Like button → Select 'Love' reaction | J18: Reaction: Love ❤️ | K18: Love reaction applied. Counter updates. Button shows ❤️ icon. | M18: Pass | N18: Functional | O18: Chrome 124 | P18: v.2026.04 | Q18: Md Sayem Mottakee | R18: 2026-04-03
A19: TC_017 | B19: Comment on a post | C19: User can write and submit a comment on any post. | D19: News Feed | E19: High | F19: Major | G19: User logged in; post visible in feed. | H19: 1 | I19: Click 'Comment' on a post → Type a comment → Press Enter | J19: Comment: 'Great post! 😊' | K19: Comment appears below post immediately with user name and avatar. | M19: Pass | N19: Functional | O19: Chrome 124 | P19: v.2026.04 | Q19: Md Sayem Mottakee | R19: 2026-04-03
A20: TC_018 | B20: Share a post to timeline | C20: User can share a post to their own timeline. | D20: News Feed | E20: High | F20: Major | G20: User logged in; shareable post visible. | H20: 1 | I20: Click 'Share' → Select 'Share to your timeline' → Add message → Click Post | J20: Share message: 'Sharing this interesting article' | K20: Post appears on user timeline. Share count on original increments. | M20: Pass | N20: Functional | O20: Chrome 124 | P20: v.2026.04 | Q20: Md Sayem Mottakee | R20: 2026-04-04
A21: TC_019 | B21: Hide a post from feed | C21: User can hide a post and it no longer appears in feed. | D21: News Feed | E21: Medium | F21: Minor | G21: User logged in; post visible in feed. | H21: 1 | I21: Click ··· (More) on any post → Select 'Hide post' | J21: N/A | K21: Post disappears from feed. Undo snackbar appears briefly. | M21: Pass | N21: Usability | O21: Chrome 124 | P21: v.2026.04 | Q21: Md Sayem Mottakee | R21: 2026-04-04
A22: TC_020 | B22: Report a post | C22: User can report a post for violating community standards. | D22: News Feed | E22: High | F22: Critical | G22: User logged in; any post visible. | H22: 1 | I22: Click ··· on post → Select 'Report post' → Choose reason → Submit | J22: Reason: 'Hate speech' | K22: Confirmation: 'Thanks for letting us know'. Report submitted. | M22: Pass | N22: Functional | O22: Chrome 124 | P22: v.2026.04 | Q22: Md Sayem Mottakee | R22: 2026-04-04
A23: TC_021 | B23: Create a text-only post | C23: User creates and publishes a plain text post to their timeline. | D23: Create Post | E23: High | F23: Critical | G23: User logged in. | H23: 1 | I23: Click 'What's on your mind?' box → Type text → Click Post | J23: Post text: 'Testing Facebook post creation ✅' | K23: Post appears on timeline and in friends feeds. Timestamp shown. | M23: Pass | N23: Functional | O23: Chrome 124 | P23: v.2026.04 | Q23: Md Sayem Mottakee | R23: 2026-04-04
A24: TC_022 | B24: Create a post with photo upload | C24: User attaches one or more photos to a post. | D24: Create Post | E24: High | F24: Critical | G24: User logged in; image file available (<25MB, JPEG). | H24: 1 | I24: Open post composer → Click Photo/Video icon → Select image file → Add caption → Click Post | J24: File: test_image.jpg (2MB, 1920×1080) | K24: Post published with image. Image renders correctly in feed. | M24: Pass | N24: Functional | O24: Chrome 124 | P24: v.2026.04 | Q24: Md Sayem Mottakee | R24: 2026-04-04
A25: TC_023 | B25: Create a post with video upload | C25: User attaches a video to a post. | D25: Create Post | E25: High | F25: Major | G25: User logged in; MP4 file <4GB available. | H25: 1 | I25: Open post composer → Click Photo/Video → Select video → Add caption → Click Post | J25: File: test_video.mp4 (50MB, 1080p, 60s) | K25: Video uploaded and post published. Video plays inline in feed with controls. | M25: Fail | N25: Functional | O25: Chrome 124 | P25: v.2026.04 | Q25: Md Sayem Mottakee | R25: 2026-04-05 | S25: FB-2215 | T25: Video stuck at 99% upload; post does not publish
A26: TC_024 | B26: Post privacy set to Friends only | C26: Post visibility can be restricted to Friends only. | D26: Create Post | E26: High | F26: Major | G26: User logged in. | H26: 1 | I26: Open post composer → Click audience selector → Select 'Friends' → Type post → Click Post | J26: Privacy: Friends | Post: 'This is a friends-only post' | K26: Post published. Audience icon shows 👥 Friends. | M26: Pass | N26: Functional | O26: Chrome 124 | P26: v.2026.04 | Q26: Md Sayem Mottakee | R26: 2026-04-05
A27: TC_025 | B27: Post with location tag | C27: User can add their current location to a post. | D27: Create Post | E27: Medium | F27: Minor | G27: User logged in; location permission granted. | H27: 1 | I27: Open post composer → Click 📍 Check in → Search 'Dhaka, Bangladesh' → Select → Click Post | J27: Location: Dhaka, Bangladesh | K27: Post includes location tag. Clicking location opens map view. | M27: Pass | N27: Functional | O27: Chrome 124 | P27: v.2026.04 | Q27: Md Sayem Mottakee | R27: 2026-04-05
A28: TC_026 | B28: Tag a friend in a post | C28: User can tag a friend in a post using @mention. | D28: Create Post | E28: Medium | F28: Minor | G28: User logged in; has at least one friend. | H28: 1 | I28: Open post composer → Type '@' + friend name → Select from suggestion → Post | J28: Tag: @TestFriend01 | K28: Friend tagged. Post shows their name as a link. | M28: Pass | N28: Functional | O28: Chrome 124 | P28: v.2026.04 | Q28: Md Sayem Mottakee | R28: 2026-04-05
A29: TC_027 | B29: Edit a published post | C29: User can edit the text of a post they already published. | D29: Create Post | E29: Medium | F29: Minor | G29: User has an existing published post. | H29: 1 | I29: Go to own timeline → Find post → Click ··· → Edit post → Modify text → Save | J29: Original: 'Hello world' → Edited: 'Hello Facebook!' | K29: Post updated with new text. 'Edited' label appears below post. | M29: Pass | N29: Functional | O29: Chrome 124 | P29: v.2026.04 | Q29: Md Sayem Mottakee | R29: 2026-04-05
A30: TC_028 | B30: Delete a published post | C30: User can permanently delete their own post. | D30: Create Post | E30: High | F30: Major | G30: User has an existing published post. | H30: 1 | I30: Go to own timeline → Find post → Click ··· → Move to Trash → Confirm Delete | J30: N/A | K30: Post removed from timeline and feed. | M30: Pass | N30: Functional | O30: Chrome 124 | P30: v.2026.04 | Q30: Md Sayem Mottakee | R30: 2026-04-05
A31: TC_029 | B31: Update profile picture | C31: User can upload a new profile picture. | D31: Profile | E31: High | F31: Major | G31: User logged in. | H31: 1 | I31: Go to profile → Click current profile picture → Select 'Upload photo' → Choose image → Crop → Save | J31: File: profile_pic.jpg (500KB) | K31: New profile picture saved. Thumbnail updated across all surfaces. | M31: Pass | N31: Functional | O31: Chrome 124 | P31: v.2026.04 | Q31: Md Sayem Mottakee | R31: 2026-04-05
A32: TC_030 | B32: Update cover photo | C32: User can upload a cover photo to their profile. | D32: Profile | E32: Medium | F32: Minor | G32: User logged in. | H32: 1 | I32: Go to profile → Click cover photo area → Upload photo → Position → Save | J32: File: cover_photo.jpg (2MB, 1640×859) | K32: Cover photo updated. Visible immediately on profile. | M32: Pass | N32: Functional | O32: Chrome 124 | P32: v.2026.04 | Q32: Md Sayem Mottakee | R32: 2026-04-05
A33: TC_031 | B33: Update bio / intro | C33: User can add or edit the bio/intro section on their profile. | D33: Profile | E33: Medium | F33: Minor | G33: User logged in. | H33: 1 | I33: Go to profile → Click 'Edit profile' → Update bio → Save | J33: Bio: 'QA Engineer | Testing the world one bug at a time 🐛' | K33: Bio saved and visible on profile. | M33: Pass | N33: Functional | O33: Chrome 124 | P33: v.2026.04 | Q33: Md Sayem Mottakee | R33: 2026-04-05
A34: TC_032 | B34: Profile visibility — privacy settings | C34: Changing profile privacy affects who can view the profile. | D34: Profile | E34: High | F34: Major | G34: User logged in; second test account available. | H34: 1 | I34: Settings → Privacy → Who can see future posts → Change to 'Only me' → Verify from second account | J34: Second account: viewer test session | K34: Profile content hidden from other viewer per selected privacy setting. | M34: Pass | N34: Functional | O34: Chrome 124 | P34: v.2026.04 | Q34: Md Sayem Mottakee | R34: 2026-04-05
A35: TC_033 | B35: Send friend request | C35: User can send a friend request to another user. | D35: Friends | E35: High | F35: Critical | G35: Two test accounts exist; not currently friends. | H35: 1 | I35: Log in as User A → Search for User B → Open profile → Click 'Add Friend' | J35: User A: Test Account A | User B: Test Account B | K35: Friend request sent. Button changes to 'Friend request sent'. | M35: Pass | N35: Functional | O35: Chrome 124 | P35: v.2026.04 | Q35: Md Sayem Mottakee | R35: 2026-04-05
A36: TC_034 | B36: Accept friend request | C36: User B can accept a pending friend request from User A. | D36: Friends | E36: High | F36: Critical | G36: Pending friend request exists. | H36: 1 | I36: Log in as User B → Go to Friend Requests → Click 'Confirm' next to User A | J36: Pending request from Test Account A | K36: Both users are now friends. Each appears in the other's friends list. | M36: Pass | N36: Functional | O36: Chrome 124 | P36: v.2026.04 | Q36: Md Sayem Mottakee | R36: 2026-04-05
A37: TC_035 | B37: Decline friend request | C37: User B can decline a friend request without connecting. | D37: Friends | E37: Medium | F37: Minor | G37: Pending friend request exists. | H37: 1 | I37: Log in as User B → Friend Requests → Click 'Delete Request' | J37: Pending request from Test Account A | K37: Request removed. No connection made. No notification sent to sender. | M37: Pass | N37: Functional | O37: Chrome 124 | P37: v.2026.04 | Q37: Md Sayem Mottakee | R37: 2026-04-05
... A45: TC_043 | B45: Receive notification for comment | C45: User notified when someone comments on their post. | D45: Notifications | E45: High | F45: Major | G45: User has a post; second friend account available. | H45: 1 | I45: Account B comments on Account A's post → Account A checks notifications | J45: Comment: 'Nice one!' | K45: Notification: '[User] commented on your post.' shown in bell dropdown. | M45: Pass | N45: Functional | O45: Chrome 124 | P45: v.2026.04 | Q45: Md Sayem Mottakee | R45: 2026-04-05
A46: TC_044 | B46: Mark all notifications as read | C46: User can mark all notifications as read at once. | D46: Notifications | E46: Medium | F46: Minor | G46: User has unread notifications. | H46: 1 | I46: Click notification bell → Click '···' → Select 'Mark all as read' | J46: N/A | K46: All notifications marked read. Badge count resets to 0. | M46: Fail | N46: Usability | O46: Chrome 124 | P46: v.2026.04 | Q46: Md Sayem Mottakee | R46: 2026-04-05 | S46: FB-2231 | T46: Badge count does not reset; requires page refresh
A47: TC_045 | B47: Search for a person by name | C47: Search returns matching user profiles. | D47: Search | E47: High | F47: Critical | G47: User logged in; searched profile exists. | H47: 1 | I47: Click search bar → Type a person's name → Press Enter → Review results | J47: Query: Test user full name | K47: Results page shows matching profiles. | M47: Pass | N47: Functional | O47: Chrome 124 | P47: v.2026.04 | Q47: Md Sayem Mottakee | R47: 2026-04-05
...

Sheet Dashboard
A1: 📊 Facebook QA — Execution Dashboard | Md Sayem Mottakee
A3: Metric | B3: Count | D3: Module | E3: Total | F3: Pass | G3: Fail | H3: Blocked
A4: Total Test Cases | B4: =COUNTA('Test Cases'!A3:A200) -> 55 | D4: Registration | E4: =COUNTIF('Test Cases'!D3:D200,D4) -> 5 | F4: =COUNTIFS('Test Cases'!D3:D200,D4,'Test Cases'!M3:M200,"Pass") -> 5 | G4: =COUNTIFS('Test Cases'!D3:D200,D4,'Test Cases'!M3:M200,"Fail") -> 0 | H4: =COUNTIFS('Test Cases'!D3:D200,D4,'Test Cases'!M3:M200,"Blocked") -> 0
A5: Passed | B5: =COUNTIF('Test Cases'!M3:M200,"Pass") -> 50 | D5: Login | E5: =COUNTIF('Test Cases'!D3:D200,D5) -> 10 | F5: =COUNTIFS('Test Cases'!D3:D200,D5,'Test Cases'!M3:M200,"Pass") -> 8 | G5: =COUNTIFS('Test Cases'!D3:D200,D5,'Test Cases'!M3:M200,"Fail") -> 2 | H5: =COUNTIFS('Test Cases'!D3:D200,D5,'Test Cases'!M3:M200,"Blocked") -> 0
A6: Failed | B6: =COUNTIF('Test Cases'!M3:M200,"Fail") -> 4 | D6: News Feed | E6: =COUNTIF('Test Cases'!D3:D200,D6) -> 10 | F6: =COUNTIFS('Test Cases'!D3:D200,D6,'Test Cases'!M3:M200,"Pass") -> 9 | G6: =COUNTIFS('Test Cases'!D3:D200,D6,'Test Cases'!M3:M200,"Fail") -> 0 | H6: =COUNTIFS('Test Cases'!D3:D200,D6,'Test Cases'!M3:M200,"Blocked") -> 1
A7: Blocked | B7: =COUNTIF('Test Cases'!M3:M200,"Blocked") -> 1 | D7: Create Post | E7: =COUNTIF('Test Cases'!D3:D200,D7) -> 8 | F7: =COUNTIFS('Test Cases'!D3:D200,D7,'Test Cases'!M3:M200,"Pass") -> 7 | G7: =COUNTIFS('Test Cases'!D3:D200,D7,'Test Cases'!M3:M200,"Fail") -> 1 | H7: =COUNTIFS('Test Cases'!D3:D200,D7,'Test Cases'!M3:M200,"Blocked") -> 0
A8: Not Run | B8: =COUNTIF('Test Cases'!M3:M200,"Not Run") -> 0 | D8: Profile | E8: =COUNTIF('Test Cases'!D3:D200,D8) -> 4 | F8: =COUNTIFS('Test Cases'!D3:D200,D8,'Test Cases'!M3:M200,"Pass") -> 4 | G8: =COUNTIFS('Test Cases'!D3:D200,D8,'Test Cases'!M3:M200,"Fail") -> 0 | H8: =COUNTIFS('Test Cases'!D3:D200,D8,'Test Cases'!M3:M200,"Blocked") -> 0
A9: Pass Rate (%) | B9: =IFERROR(COUNTIF('Test Cases'!M3:M200,"Pass")/COUNTA('Test Cases'!A3:A200)*100,0) -> 90.909091 | D9: Friends | E9: =COUNTIF('Test Cases'!D3:D200,D9) -> 5 | F9: =COUNTIFS('Test Cases'!D3:D200,D9,'Test Cases'!M3:M200,"Pass") -> 5 | G9: =COUNTIFS('Test Cases'!D3:D200,D9,'Test Cases'!M3:M200,"Fail") -> 0 | H9: =COUNTIFS('Test Cases'!D3:D200,D9,'Test Cases'!M3:M200,"Blocked") -> 0
A10: Fail Rate (%) | B10: =IFERROR(COUNTIF('Test Cases'!M3:M200,"Fail")/COUNTA('Test Cases'!A3:A200)*100,0) -> 7.2727273 | D10: Messaging | E10: =COUNTIF('Test Cases'!D3:D200,D10) -> 4 | F10: =COUNTIFS('Test Cases'!D3:D200,D10,'Test Cases'!M3:M200,"Pass") -> 4 | G10: =COUNTIFS('Test Cases'!D3:D200,D10,'Test Cases'!M3:M200,"Fail") -> 0 | H10: =COUNTIFS('Test Cases'!D3:D200,D10,'Test Cases'!M3:M200,"Blocked") -> 0
A11: High Priority TCs | B11: =COUNTIF('Test Cases'!E3:E200,"High") -> 35 | D11: Notifications | E11: =COUNTIF('Test Cases'!D3:D200,D11) -> 3 | F11: =COUNTIFS('Test Cases'!D3:D200,D11,'Test Cases'!M3:M200,"Pass") -> 2 | G11: =COUNTIFS('Test Cases'!D3:D200,D11,'Test Cases'!M3:M200,"Fail") -> 1 | H11: =COUNTIFS('Test Cases'!D3:D200,D11,'Test Cases'!M3:M200,"Blocked") -> 0
A12: Critical Severity | B12: =COUNTIF('Test Cases'!F3:F200,"Critical") -> 17 | D12: Search | E12: =COUNTIF('Test Cases'!D3:D200,D12) -> 3 | F12: =COUNTIFS('Test Cases'!D3:D200,D12,'Test Cases'!M3:M200,"Pass") -> 3 | G12: =COUNTIFS('Test Cases'!D3:D200,D12,'Test Cases'!M3:M200,"Fail") -> 0 | H12: =COUNTIFS('Test Cases'!D3:D200,D12,'Test Cases'!M3:M200,"Blocked") -> 0
D13: Groups | E13: =COUNTIF('Test Cases'!D3:D200,D13) -> 2 | F13: =COUNTIFS('Test Cases'!D3:D200,D13,'Test Cases'!M3:M200,"Pass") -> 2 | G13: =COUNTIFS('Test Cases'!D3:D200,D13,'Test Cases'!M3:M200,"Fail") -> 0 | H13: =COUNTIFS('Test Cases'!D3:D200,D13,'Test Cases'!M3:M200,"Blocked") -> 0
D14: Marketplace | E14: =COUNTIF('Test Cases'!D3:D200,D14) -> 1 | F14: =COUNTIFS('Test Cases'!D3:D200,D14,'Test Cases'!M3:M200,"Pass") -> 1 | G14: =COUNTIFS('Test Cases'!D3:D200,D14,'Test Cases'!M3:M200,"Fail") -> 0 | H14: =COUNTIFS('Test Cases'!D3:D200,D14,'Test Cases'!M3:M200,"Blocked") -> 0

Sheet Jira
A1: Summary | B1: Precondition | C1: Priority | D1: Test Step | E1: Test Data | F1: Expected Result
A2: Register with valid email | B2: Browser open; email not previously registered; internet connected. | C2: High | D2: Go to facebook.com → Click 'Create new account' → Fill all fields with valid data → Click 'Sign Up' | E2: Name: Md Sayem Mottakee | Email: sayemmottakee2000@gmail.com | DOB: 01/Jan/1995 | Pass: Test@1234! | F2: Account created; confirmation email sent; user lands on confirm email screen.
A3: Register with already-used email | B3: Existing account linked to test email. | C3: High | D3: Go to Sign Up → Enter already-registered email → Fill remaining fields → Click Sign Up | E3: Email: sayemmottakee2000@gmail.com (already registered) | F3: Error: 'It looks like you already have an account' displayed. Registration blocked.
A4: Register with invalid email format | B4: None. | C4: Medium | D4: Go to Sign Up → Enter invalid email → Fill other fields → Click Sign Up | E4: Email: notanemail@@bad | Pass: Test@1234! | F4: Inline validation error on email field. Form does not submit.
A5: Register with weak password | B5: None. | C5: High | D5: Go to Sign Up → Fill valid name/email/DOB → Enter weak password → Click Sign Up | E5: Password: 123456 | F5: Error: 'Choose a more secure password' shown. Account not created.
A6: Register with underage DOB | B6: None. | C6: High | D6: Go to Sign Up → Enter DOB yielding age < 13 → Complete other fields → Click Sign Up | E6: DOB: 01/Jan/2015 (age 11) | F6: Error displayed; account creation blocked with age policy message.
A7: Login with valid credentials | B7: Valid registered account exists. | C7: High | D7: Go to facebook.com → Enter valid email and password → Click 'Log In' | E7: Email: sayemmottakee2000@gmail.com | Pass: Test@1234! | F7: User lands on News Feed. Name displayed in top nav.
A8: Login with wrong password | B8: Valid account exists. | C8: High | D8: Go to facebook.com → Enter valid email → Enter wrong password → Click Log In | E8: Email: sayemmottakee2000@gmail.com | Pass: WrongPass99 | F8: Error: 'The password you've entered is incorrect.' Login denied.
A9: Login with unregistered email | B9: None. | C9: Medium | D9: Go to facebook.com → Enter unregistered email → Any password → Click Log In | E9: Email: nobody@fake.net | Pass: Test@1234! | F9: Error: 'The email address you entered isn't connected to an account.'
A10: Account lockout after repeated failed logins | B10: Valid account exists. | C10: High | D10: Attempt login with wrong password 5 times consecutively | E10: Email: sayemmottakee2000@gmail.com | Wrong password repeated 5x | F10: Lockout message displayed. CAPTCHA or cooldown enforced.
A11: Forgot password — reset via email | B11: Account exists; email inbox accessible. | C11: High | D11: Click 'Forgotten password?' → Enter email → Click Search → Click 'Send code' → Open email → Enter code → Set new password | E11: Email: sayemmottakee2000@gmail.com | New pass: NewPass@5678! | F11: Password reset. User can log in with new password immediately.
A12: Remember me / stay logged in | B12: User is on login page. | C12: Medium | D12: Enter valid credentials → Check 'Stay logged in' → Log in → Close browser → Reopen → Navigate to facebook.com | E12: Same browser session, no incognito | F12: User remains logged in; News Feed loads without prompting for credentials.
... A56: Accessibility — keyboard navigation on login page | B56: Browser with no mouse interaction. | C56: Medium | D56: Navigate to facebook.com/login → Use Tab to move between fields → Use Enter to submit | E56: Keyboard only navigation | F56: Email, Password, Forgot Password, Log In, Create Account — all reachable via Tab. Submit via Enter works.
